multiprocessing.pool.RemoteTraceback: 
"""
Traceback (most recent call last):
  File "/data/modules/python/3.6.0/lib/python3.6/multiprocessing/pool.py", line 119, in worker
    result = (True, func(*args, **kwds))
  File "/data/modules/python/3.6.0/lib/python3.6/multiprocessing/pool.py", line 44, in mapstar
    return list(map(*args))
  File "/data/modules/python/3.6.0/lib/python3.6/site-packages/ldpop/lookup_table.py", line 52, in getColumnHelper
    return getColumn(*args)
  File "/data/modules/python/3.6.0/lib/python3.6/site-packages/ldpop/lookup_table.py", line 62, in getColumn
    lastEpochInit=init)
  File "/data/modules/python/3.6.0/lib/python3.6/site-packages/ldpop/compute_likelihoods.py", line 110, in folded_likelihoods
    assert abs(currTime) < 1e-15, str(currTime)
AssertionError: 1.7763568394002505e-15
"""

The above exception was the direct cause of the following exception:

Traceback (most recent call last):
  File "/data/modules/python/3.6.0/bin/pyrho", line 11, in <module>
    load_entry_point('pyrho==0.1.3', 'console_scripts', 'pyrho')()
  File "/data/modules/python/3.6.0/lib/python3.6/site-packages/pyrho/frontend.py", line 67, in main
    func(args)
  File "/data/modules/python/3.6.0/lib/python3.6/site-packages/pyrho/make_table.py", line 122, in _main
    load_stationary=args.load_stationary).table
  File "/data/modules/python/3.6.0/lib/python3.6/site-packages/ldpop/lookup_table.py", line 170, in __init__
    load_stationary)
  File "/data/modules/python/3.6.0/lib/python3.6/site-packages/ldpop/lookup_table.py", line 101, in computeLikelihoods
    for rho, prevInit in zip(reversed(rhoGrid), inits)])
  File "/data/modules/python/3.6.0/lib/python3.6/multiprocessing/pool.py", line 260, in map
    return self._map_async(func, iterable, mapstar, chunksize).get()
  File "/data/modules/python/3.6.0/lib/python3.6/multiprocessing/pool.py", line 608, in get
    raise self._value
AssertionError: 1.7763568394002505e-15
